<?xml version="1.0" ?>
<!-- ***************************************************************** 
 ****** File automatically generated by generate_urdf.py script ****** 
 ********************************************************************* -->
<robot xmlns:xacro="http://www.ros.org/wiki/xacro">
	<link name="base_link"/>
	<joint name="base_joint" type="fixed">
		<parent link="base_link"/>
		<child link="torso"/>
		<origin rpy="0 0 0" xyz="0 0 0"/>
	</joint>
	<link name="torso">
		<inertial>
			<mass value="9.9216"/>
			<inertia ixx="0.129332" ixy="-0.000359651" ixz="0.00283888" iyy="0.126831" iyz="-0.00200843" izz="0.110627"/>
			<origin rpy="0 0 0" xyz="0.0023 0 -0.04854"/>
		</inertial>
		<xacro:insert_visu_torso/>
	</link>
	<joint name="TrunkYaw" type="revolute">
		<parent link="torso"/>
		<child link="body"/>
		<origin rpy="0 0 0" xyz="0 0 -0.2"/>
		<axis xyz="0 0 1.0"/>
		<limit effort="80.902" lower="-0.785398" upper="0.785398" velocity="1.5"/>
	</joint>
	<link name="body">
		<inertial>
			<mass value="4.16277"/>
			<inertia ixx="0.241879" ixy="-6.88963e-05" ixz="0.00282915" iyy="0.238168" iyz="0.000306252" izz="0.0214739"/>
			<origin rpy="0 0 0" xyz="0.00932 0 -0.2119"/>
		</inertial>
		<xacro:insert_visu_body/>
	</link>
</robot>
