<?xml version="1.0" ?>
<!-- ***************************************************************** 
 ****** File automatically generated by generate_urdf.py script ****** 
 ********************************************************************* -->
<robot xmlns:xacro="http://www.ros.org/wiki/xacro">
	<joint name="NeckYaw" type="revolute">
		<parent link="torso"/>
		<child link="NeckYawLink"/>
		<origin rpy="0 0 0" xyz="0 0 0.0835"/>
		<axis xyz="0 0 1.0"/>
		<limit effort="3.662" lower="-1.5708" upper="1.5708" velocity="4.0"/>
	</joint>
	<link name="NeckYawLink">
		<inertial>
			<mass value="0.51016"/>
			<inertia ixx="0.00122159" ixy="-8.014e-08" ixz="1.145e-08" iyy="0.00124608" iyz="-1.84095e-06" izz="0.000187965"/>
			<origin rpy="0 0 0" xyz="0 0 -0.03074"/>
		</inertial>
	</link>
	<joint name="NeckPitch" type="revolute">
		<parent link="NeckYawLink"/>
		<child link="NeckPitchLink"/>
		<origin rpy="0 0 0" xyz="0 0 0"/>
		<axis xyz="0 1.0 0"/>
		<limit effort="2.978" lower="-0.349066" upper="0.698132" velocity="2.2"/>
	</joint>
	<link name="NeckPitchLink">
		<inertial>
			<mass value="0.23875"/>
			<inertia ixx="0.000866022" ixy="-1.57263e-06" ixz="6.13825e-05" iyy="0.000818287" iyz="9.69515e-06" izz="0.000238919"/>
			<origin rpy="0 0 0" xyz="-0.00472 0 0.04432"/>
		</inertial>
		<xacro:insert_visu_NeckPitchLink/>
	</link>
	<joint name="HeadPitch" type="revolute">
		<parent link="NeckPitchLink"/>
		<child link="HeadPitchLink"/>
		<origin rpy="0 0 0" xyz="0 0 0.09511"/>
		<axis xyz="0 1.0 0"/>
		<limit effort="2.57" lower="-0.349066" upper="0.279253" velocity="1.9"/>
	</joint>
	<link name="HeadPitchLink">
		<inertial>
			<mass value="0.13981"/>
			<inertia ixx="3.89601e-05" ixy="-3.814e-08" ixz="-2.29622e-06" iyy="7.25465e-05" iyz="-6.46e-09" izz="5.3765e-05"/>
			<origin rpy="0 0 0" xyz="0.00137 0 -0.00641"/>
		</inertial>
	</link>
	<joint name="HeadRoll" type="revolute">
		<parent link="HeadPitchLink"/>
		<child link="HeadRollLink"/>
		<origin rpy="0 0 0" xyz="0 0 0"/>
		<axis xyz="1.0 0 0"/>
		<limit effort="0.9" lower="-0.349066" upper="0.349066" velocity="1.5"/>
	</joint>
	<link name="HeadRollLink">
		<inertial>
			<mass value="1.41282"/>
			<inertia ixx="0.0149087" ixy="-5.14209e-05" ixz="-0.000684893" iyy="0.0173189" iyz="-0.000191527" izz="0.00735475"/>
			<origin rpy="0 0 0" xyz="0.01617 0 0.00757"/>
		</inertial>
		<xacro:insert_visu_HeadRollLink/>
	</link>
	<joint name="gaze_joint" type="fixed">
		<parent link="HeadRollLink"/>
		<child link="gaze"/>
		<origin rpy="0 0 0" xyz="0.11017 0 0.05426"/>
	</joint>
	<link name="gaze"/>
</robot>
