<?xml version="1.0"?>

<!-- This file has been created by hand based on the work of LAAS https://github.com/laas/romeo/blob/master/romeo_description -->
<robot xmlns:xacro="http://www.ros.org/wiki/xacro">

<joint name="l_gripper_joint" type="fixed">
  <parent link="l_wrist"/>
  <child link="l_gripper"/>
  <origin xyz="0.09 0 -0.02" rpy="-1.57079633 0 0"/>
</joint>
<link name="l_gripper"/>
<joint name="r_gripper_joint" type="fixed">
  <parent link="r_wrist"/>
  <child link="r_gripper"/>
  <origin xyz="0.09 0 -0.02" rpy="-1.57079633 0 0"/>
</joint>
<link name="r_gripper"/>

<!--  Fingers -->
<!-- Fingers -->
  <link name="LFinger11Link">
    <inertial>
      <origin xyz="0 0 0" rpy="0 0 0"/>
      <mass value="0"/>
      <inertia ixx="0" ixy="0" ixz="0" iyy="0" iyz="0" izz="0" />
    </inertial>
    <visual>
      <origin xyz="0 0 0" rpy="0 0 0" />
      <geometry>
	<mesh filename="package://romeo_description/meshes/V1/visual/Phalax.dae" />
      </geometry>
    </visual>
    <collision>
      <origin xyz="0 0 0" rpy="0 0 0" />
      <geometry>
	<mesh filename="package://romeo_description/meshes/V1/collision/Phalax.dae" />
      </geometry>
    </collision>
  </link>

  <link name="LFinger12Link">
    <inertial>
      <origin xyz="0 0 0" rpy="0 0 0"/>
      <mass value="0"/>
      <inertia ixx="0" ixy="0" ixz="0" iyy="0" iyz="0" izz="0" />
    </inertial>
    <visual>
      <origin xyz="0 0 0" rpy="0 0 0" />
      <geometry>
	<mesh filename="package://romeo_description/meshes/V1/visual/Phalax.dae" />
      </geometry>
    </visual>
    <collision>
      <origin xyz="0 0 0" rpy="0 0 0" />
      <geometry>
	<mesh filename="package://romeo_description/meshes/V1/collision/Phalax.dae" />
      </geometry>
    </collision>
  </link>

  <link name="LFinger13Link">
    <inertial>
      <origin xyz="0 0 0" rpy="0 0 0"/>
      <mass value="0"/>
      <inertia ixx="0" ixy="0" ixz="0" iyy="0" iyz="0" izz="0" />
    </inertial>
    <visual>
      <origin xyz="0 0 0" rpy="0 0 0" />
      <geometry>
	<mesh filename="package://romeo_description/meshes/V1/visual/PhalaxEnd.dae" />
      </geometry>
    </visual>
    <collision>
      <origin xyz="0 0 0" rpy="0 0 0" />
      <geometry>
	<mesh filename="package://romeo_description/meshes/V1/collision/PhalaxEnd.dae" />
      </geometry>
    </collision>
  </link>

  <link name="LFinger21Link">
    <inertial>
      <origin xyz="0 0 0" rpy="0 0 0"/>
      <mass value="0"/>
      <inertia ixx="0" ixy="0" ixz="0" iyy="0" iyz="0" izz="0" />
    </inertial>
    <visual>
      <origin xyz="0 0 0" rpy="0 0 0" />
      <geometry>
	<mesh filename="package://romeo_description/meshes/V1/visual/Phalax.dae" />
      </geometry>
    </visual>
    <collision>
      <origin xyz="0 0 0" rpy="0 0 0" />
      <geometry>
	<mesh filename="package://romeo_description/meshes/V1/collision/Phalax.dae" />
      </geometry>
    </collision>
  </link>

  <link name="LFinger22Link">
    <inertial>
      <origin xyz="0 0 0" rpy="0 0 0"/>
      <mass value="0"/>
      <inertia ixx="0" ixy="0" ixz="0" iyy="0" iyz="0" izz="0" />
    </inertial>
    <visual>
      <origin xyz="0 0 0" rpy="0 0 0" />
      <geometry>
	<mesh filename="package://romeo_description/meshes/V1/visual/Phalax.dae" />
      </geometry>
    </visual>
    <collision>
      <origin xyz="0 0 0" rpy="0 0 0" />
      <geometry>
	<mesh filename="package://romeo_description/meshes/V1/collision/Phalax.dae" />
      </geometry>
    </collision>
  </link>

  <link name="LFinger23Link">
    <inertial>
      <origin xyz="0 0 0" rpy="0 0 0"/>
      <mass value="0"/>
      <inertia ixx="0" ixy="0" ixz="0" iyy="0" iyz="0" izz="0" />
    </inertial>
    <visual>
      <origin xyz="0 0 0" rpy="0 0 0" />
      <geometry>
	<mesh filename="package://romeo_description/meshes/V1/visual/PhalaxEnd.dae" />
      </geometry>
    </visual>
    <collision>
      <origin xyz="0 0 0" rpy="0 0 0" />
      <geometry>
	<mesh filename="package://romeo_description/meshes/V1/collision/PhalaxEnd.dae" />
      </geometry>
    </collision>
  </link>

  <link name="LFinger31Link">
    <inertial>
      <origin xyz="0 0 0" rpy="0 0 0"/>
      <mass value="0"/>
      <inertia ixx="0" ixy="0" ixz="0" iyy="0" iyz="0" izz="0" />
    </inertial>
    <visual>
      <origin xyz="0 0 0" rpy="0 0 0" />
      <geometry>
	<mesh filename="package://romeo_description/meshes/V1/visual/Phalax.dae" />
      </geometry>
    </visual>
    <collision>
      <origin xyz="0 0 0" rpy="0 0 0" />
      <geometry>
	<mesh filename="package://romeo_description/meshes/V1/collision/Phalax.dae" />
      </geometry>
    </collision>
  </link>

  <link name="LFinger32Link">
    <inertial>
      <origin xyz="0 0 0" rpy="0 0 0"/>
      <mass value="0"/>
      <inertia ixx="0" ixy="0" ixz="0" iyy="0" iyz="0" izz="0" />
    </inertial>
    <visual>
      <origin xyz="0 0 0" rpy="0 0 0" />
      <geometry>
	<mesh filename="package://romeo_description/meshes/V1/visual/Phalax.dae" />
      </geometry>
    </visual>
    <collision>
      <origin xyz="0 0 0" rpy="0 0 0" />
      <geometry>
	<mesh filename="package://romeo_description/meshes/V1/collision/Phalax.dae" />
      </geometry>
    </collision>
  </link>

  <link name="LFinger33Link">
    <inertial>
      <origin xyz="0 0 0" rpy="0 0 0"/>
      <mass value="0"/>
      <inertia ixx="0" ixy="0" ixz="0" iyy="0" iyz="0" izz="0" />
    </inertial>
    <visual>
      <origin xyz="0 0 0" rpy="0 0 0" />
      <geometry>
	<mesh filename="package://romeo_description/meshes/V1/visual/PhalaxEnd.dae" />
      </geometry>
    </visual>
    <collision>
      <origin xyz="0 0 0" rpy="0 0 0" />
      <geometry>
	<mesh filename="package://romeo_description/meshes/V1/collision/PhalaxEnd.dae" />
      </geometry>
    </collision>
  </link>

  <link name="LThumb1Link">
    <inertial>
      <origin xyz="0 0 0" rpy="0 0 0"/>
      <mass value="0"/>
      <inertia ixx="0" ixy="0" ixz="0" iyy="0" iyz="0" izz="0" />
    </inertial>
    <visual>
      <origin xyz="0 0 0" rpy="0 0 0" />
      <geometry>
	<mesh filename="package://romeo_description/meshes/V1/visual/LThumb.dae" />
      </geometry>
    </visual>
    <collision>
      <origin xyz="0 0 0" rpy="0 0 0" />
      <geometry>
	<mesh filename="package://romeo_description/meshes/V1/collision/LThumb.dae" />
      </geometry>
    </collision>
  </link>

  <link name="LThumb2Link">
    <inertial>
      <origin xyz="0 0 0" rpy="0 0 0"/>
      <mass value="0"/>
      <inertia ixx="0" ixy="0" ixz="0" iyy="0" iyz="0" izz="0" />
    </inertial>
    <visual>
      <origin xyz="0 0 0" rpy="0 0 0" />
      <geometry>
	<mesh filename="package://romeo_description/meshes/V1/visual/Phalax.dae" />
      </geometry>
    </visual>
    <collision>
      <origin xyz="0 0 0" rpy="0 0 0" />
      <geometry>
	<mesh filename="package://romeo_description/meshes/V1/collision/Phalax.dae" />
      </geometry>
    </collision>
  </link>

  <link name="LThumb3Link">
    <inertial>
      <origin xyz="0 0 0" rpy="0 0 0"/>
      <mass value="0"/>
      <inertia ixx="0" ixy="0" ixz="0" iyy="0" iyz="0" izz="0" />
    </inertial>
    <visual>
      <origin xyz="0 0 0" rpy="0 0 0" />
      <geometry>
	<mesh filename="package://romeo_description/meshes/V1/visual/PhalaxEnd.dae" />
      </geometry>
    </visual>
    <collision>
      <origin xyz="0 0 0" rpy="0 0 0" />
      <geometry>
	<mesh filename="package://romeo_description/meshes/V1/collision/PhalaxEnd.dae" />
      </geometry>
    </collision>
  </link>

  <link name="RFinger11Link">
    <inertial>
      <origin xyz="0 0 0" rpy="0 0 0"/>
      <mass value="0"/>
      <inertia ixx="0" ixy="0" ixz="0" iyy="0" iyz="0" izz="0" />
    </inertial>
    <visual>
      <origin xyz="0 0 0" rpy="0 0 0" />
      <geometry>
	<mesh filename="package://romeo_description/meshes/V1/visual/Phalax.dae" />
      </geometry>
    </visual>
    <collision>
      <origin xyz="0 0 0" rpy="0 0 0" />
      <geometry>
	<mesh filename="package://romeo_description/meshes/V1/collision/Phalax.dae" />
      </geometry>
    </collision>
  </link>

  <link name="RFinger12Link">
    <inertial>
      <origin xyz="0 0 0" rpy="0 0 0"/>
      <mass value="0"/>
      <inertia ixx="0" ixy="0" ixz="0" iyy="0" iyz="0" izz="0" />
    </inertial>
    <visual>
      <origin xyz="0 0 0" rpy="0 0 0" />
      <geometry>
	<mesh filename="package://romeo_description/meshes/V1/visual/Phalax.dae" />
      </geometry>
    </visual>
    <collision>
      <origin xyz="0 0 0" rpy="0 0 0" />
      <geometry>
	<mesh filename="package://romeo_description/meshes/V1/collision/Phalax.dae" />
      </geometry>
    </collision>
  </link>

  <link name="RFinger13Link">
    <inertial>
      <origin xyz="0 0 0" rpy="0 0 0"/>
      <mass value="0"/>
      <inertia ixx="0" ixy="0" ixz="0" iyy="0" iyz="0" izz="0" />
    </inertial>
    <visual>
      <origin xyz="0 0 0" rpy="0 0 0" />
      <geometry>
	<mesh filename="package://romeo_description/meshes/V1/visual/PhalaxEnd.dae" />
      </geometry>
    </visual>
    <collision>
      <origin xyz="0 0 0" rpy="0 0 0" />
      <geometry>
	<mesh filename="package://romeo_description/meshes/V1/collision/PhalaxEnd.dae" />
      </geometry>
    </collision>
  </link>

  <link name="RFinger21Link">
    <inertial>
      <origin xyz="0 0 0" rpy="0 0 0"/>
      <mass value="0"/>
      <inertia ixx="0" ixy="0" ixz="0" iyy="0" iyz="0" izz="0" />
    </inertial>
    <visual>
      <origin xyz="0 0 0" rpy="0 0 0" />
      <geometry>
	<mesh filename="package://romeo_description/meshes/V1/visual/Phalax.dae" />
      </geometry>
    </visual>
    <collision>
      <origin xyz="0 0 0" rpy="0 0 0" />
      <geometry>
	<mesh filename="package://romeo_description/meshes/V1/collision/Phalax.dae" />
      </geometry>
    </collision>
  </link>

  <link name="RFinger22Link">
    <inertial>
      <origin xyz="0 0 0" rpy="0 0 0"/>
      <mass value="0"/>
      <inertia ixx="0" ixy="0" ixz="0" iyy="0" iyz="0" izz="0" />
    </inertial>
    <visual>
      <origin xyz="0 0 0" rpy="0 0 0" />
      <geometry>
	<mesh filename="package://romeo_description/meshes/V1/visual/Phalax.dae" />
      </geometry>
    </visual>
    <collision>
      <origin xyz="0 0 0" rpy="0 0 0" />
      <geometry>
	<mesh filename="package://romeo_description/meshes/V1/collision/Phalax.dae" />
      </geometry>
    </collision>
  </link>

  <link name="RFinger23Link">
    <inertial>
      <origin xyz="0 0 0" rpy="0 0 0"/>
      <mass value="0"/>
      <inertia ixx="0" ixy="0" ixz="0" iyy="0" iyz="0" izz="0" />
    </inertial>
    <visual>
      <origin xyz="0 0 0" rpy="0 0 0" />
      <geometry>
	<mesh filename="package://romeo_description/meshes/V1/visual/PhalaxEnd.dae" />
      </geometry>
    </visual>
    <collision>
      <origin xyz="0 0 0" rpy="0 0 0" />
      <geometry>
	<mesh filename="package://romeo_description/meshes/V1/collision/PhalaxEnd.dae" />
      </geometry>
    </collision>
  </link>

  <link name="RFinger31Link">
    <inertial>
      <origin xyz="0 0 0" rpy="0 0 0"/>
      <mass value="0"/>
      <inertia ixx="0" ixy="0" ixz="0" iyy="0" iyz="0" izz="0" />
    </inertial>
    <visual>
      <origin xyz="0 0 0" rpy="0 0 0" />
      <geometry>
	<mesh filename="package://romeo_description/meshes/V1/visual/Phalax.dae" />
      </geometry>
    </visual>
    <collision>
      <origin xyz="0 0 0" rpy="0 0 0" />
      <geometry>
	<mesh filename="package://romeo_description/meshes/V1/collision/Phalax.dae" />
      </geometry>
    </collision>
  </link>

  <link name="RFinger32Link">
    <inertial>
      <origin xyz="0 0 0" rpy="0 0 0"/>
      <mass value="0"/>
      <inertia ixx="0" ixy="0" ixz="0" iyy="0" iyz="0" izz="0" />
    </inertial>
    <visual>
      <origin xyz="0 0 0" rpy="0 0 0" />
      <geometry>
	<mesh filename="package://romeo_description/meshes/V1/visual/Phalax.dae" />
      </geometry>
    </visual>
    <collision>
      <origin xyz="0 0 0" rpy="0 0 0" />
      <geometry>
	<mesh filename="package://romeo_description/meshes/V1/collision/Phalax.dae" />
      </geometry>
    </collision>
  </link>

  <link name="RFinger33Link">
    <inertial>
      <origin xyz="0 0 0" rpy="0 0 0"/>
      <mass value="0"/>
      <inertia ixx="0" ixy="0" ixz="0" iyy="0" iyz="0" izz="0" />
    </inertial>
    <visual>
      <origin xyz="0 0 0" rpy="0 0 0" />
      <geometry>
	<mesh filename="package://romeo_description/meshes/V1/visual/PhalaxEnd.dae" />
      </geometry>
    </visual>
    <collision>
      <origin xyz="0 0 0" rpy="0 0 0" />
      <geometry>
	<mesh filename="package://romeo_description/meshes/V1/collision/PhalaxEnd.dae" />
      </geometry>
    </collision>
  </link>

  <link name="RThumb1Link">
    <inertial>
      <origin xyz="0 0 0" rpy="0 0 0"/>
      <mass value="0"/>
      <inertia ixx="0" ixy="0" ixz="0" iyy="0" iyz="0" izz="0" />
    </inertial>
    <visual>
      <origin xyz="0 0 0" rpy="0 0 0" />
      <geometry>
	<mesh filename="package://romeo_description/meshes/V1/visual/RThumb.dae" />
      </geometry>
    </visual>
    <collision>
      <origin xyz="0 0 0" rpy="0 0 0" />
      <geometry>
	<mesh filename="package://romeo_description/meshes/V1/collision/RThumb.dae" />
      </geometry>
    </collision>
  </link>

  <link name="RThumb2Link">
    <inertial>
      <origin xyz="0 0 0" rpy="0 0 0"/>
      <mass value="0"/>
      <inertia ixx="0" ixy="0" ixz="0" iyy="0" iyz="0" izz="0" />
    </inertial>
    <visual>
      <origin xyz="0 0 0" rpy="0 0 0" />
      <geometry>
	<mesh filename="package://romeo_description/meshes/V1/visual/Phalax.dae" />
      </geometry>
    </visual>
    <collision>
      <origin xyz="0 0 0" rpy="0 0 0" />
      <geometry>
	<mesh filename="package://romeo_description/meshes/V1/collision/Phalax.dae" />
      </geometry>
    </collision>
  </link>

  <link name="RThumb3Link">
    <inertial>
      <origin xyz="0 0 0" rpy="0 0 0"/>
      <mass value="0"/>
      <inertia ixx="0" ixy="0" ixz="0" iyy="0" iyz="0" izz="0" />
    </inertial>
    <visual>
      <origin xyz="0 0 0" rpy="0 0 0" />
      <geometry>
	<mesh filename="package://romeo_description/meshes/V1/visual/PhalaxEnd.dae" />
      </geometry>
    </visual>
    <collision>
      <origin xyz="0 0 0" rpy="0 0 0" />
      <geometry>
	<mesh filename="package://romeo_description/meshes/V1/collision/PhalaxEnd.dae" />
      </geometry>
    </collision>
  </link>


<!-- Finger joints -->
    <joint name="LHand" type="revolute">
      <origin xyz="0.10937 0.02468 0.00329" rpy="2.98023e-08 1.06465 0.122173"/>
      <axis xyz="0.121869 -0.992546 -4.37114e-08"/>
      <parent link="l_wrist"/>
      <child link="LFinger11Link"/>
<!--      <limit effort="0" lower="-4.266806" upper="0.0" velocity="0" /> -->
      <limit effort="0" lower="0.0" upper="1.0" velocity="0" />
    </joint>
    <joint name="RHand" type="revolute">
      <origin xyz="0.10937 -0.02468 0.00329" rpy="3.72529e-08 1.06465 -0.122173"/>
      <axis xyz="-0.121869 -0.992546 -4.37114e-08"/>
      <parent link="r_wrist"/>
      <child link="RFinger11Link"/>
      <limit effort="0" lower="-4.266806" upper="0.0" velocity="0" />
    </joint>

<!-- Finger joints -->
  <joint name="LFinger12" type="revolute">
    <origin xyz="0.01818 0 0" rpy="4.64506e-08 1.06465 7.88574e-08"/>
    <axis xyz="0 -1 -4.37114e-08"/>
    <parent link="LFinger11Link"/>
    <child link="LFinger12Link"/>
    <limit effort="0" lower="0" upper="1.06465082555556" velocity="0" />
<!--    <mimic joint="LFinger11" multiplier="1" offset="0"/> -->     <mimic joint="LHand" multiplier="1" offset="0"/>
  </joint>

  <joint name="LFinger13" type="revolute">
    <origin xyz="0.01818 0 0" rpy="4.64506e-08 1.06465 7.88574e-08"/>
    <axis xyz="0 -1 -4.37114e-08"/>
    <parent link="LFinger12Link"/>
    <child link="LFinger13Link"/>
    <limit effort="0" lower="0" upper="1.06465082555556" velocity="0" />
<!--    <mimic joint="LFinger11" multiplier="1" offset="0"/> -->     <mimic joint="LHand" multiplier="1" offset="0"/>
  </joint>

  <joint name="LFinger21" type="revolute">
    <origin xyz="0.11525 0 0.00329" rpy="4.64506e-08 1.06465 7.88574e-08"/>
    <axis xyz="0 -1 -4.37114e-08"/>
    <parent link="l_wrist"/>
    <child link="LFinger21Link"/>
    <limit effort="0" lower="0" upper="1.06465082555556" velocity="0" />
<!--    <mimic joint="LFinger11" multiplier="1" offset="0"/> -->     <mimic joint="LHand" multiplier="1" offset="0"/>
  </joint>

  <joint name="LFinger22" type="revolute">
    <origin xyz="0.01818 0 0" rpy="4.64506e-08 1.06465 7.88574e-08"/>
    <axis xyz="0 -1 -4.37114e-08"/>
    <parent link="LFinger21Link"/>
    <child link="LFinger22Link"/>
    <limit effort="0" lower="0" upper="1.06465082555556" velocity="0" />
<!--    <mimic joint="LFinger11" multiplier="1" offset="0"/> -->     <mimic joint="LHand" multiplier="1" offset="0"/>
  </joint>

  <joint name="LFinger23" type="revolute">
    <origin xyz="0.01818 0 0" rpy="4.64506e-08 1.06465 7.88574e-08"/>
    <axis xyz="0 -1 -4.37114e-08"/>
    <parent link="LFinger22Link"/>
    <child link="LFinger23Link"/>
    <limit effort="0" lower="0" upper="1.06465082555556" velocity="0" />
<!--    <mimic joint="LFinger11" multiplier="1" offset="0"/> -->     <mimic joint="LHand" multiplier="1" offset="0"/>
  </joint>

  <joint name="LFinger31" type="revolute">
    <origin xyz="0.09936 -0.02478 0.00329" rpy="3.72529e-08 1.06465 -0.122173"/>
    <axis xyz="-0.121869 -0.992546 -4.37114e-08"/>
    <parent link="l_wrist"/>
    <child link="LFinger31Link"/>
    <limit effort="0" lower="0" upper="1.06465082555556" velocity="0" />
<!--    <mimic joint="LFinger11" multiplier="1" offset="0"/> -->     <mimic joint="LHand" multiplier="1" offset="0"/>
  </joint>

  <joint name="LFinger32" type="revolute">
    <origin xyz="0.01818 0 0" rpy="4.64506e-08 1.06465 7.88574e-08"/>
    <axis xyz="0 -1 -4.37114e-08"/>
    <parent link="LFinger31Link"/>
    <child link="LFinger32Link"/>
    <limit effort="0" lower="0" upper="1.06465082555556" velocity="0" />
<!--    <mimic joint="LFinger11" multiplier="1" offset="0"/> -->     <mimic joint="LHand" multiplier="1" offset="0"/>
  </joint>

  <joint name="LFinger33" type="revolute">
    <origin xyz="0.01818 0 0" rpy="4.64506e-08 1.06465 7.88574e-08"/>
    <axis xyz="0 -1 -4.37114e-08"/>
    <parent link="LFinger32Link"/>
    <child link="LFinger33Link"/>
    <limit effort="0" lower="0" upper="1.06465082555556" velocity="0" />
<!--    <mimic joint="LFinger11" multiplier="1" offset="0"/> -->     <mimic joint="LHand" multiplier="1" offset="0"/>
  </joint>

  <joint name="LThumb1" type="revolute">
    <origin xyz="0.07115 -0.02465 -0.01233" rpy="-4.76837e-07 1.37881 -2.53073"/>
    <axis xyz="-0.573576 0.819152 1.05097e-07"/>
    <parent link="l_wrist"/>
    <child link="LThumb1Link"/>
    <limit effort="0" lower="-1.06465082555556" upper="0" velocity="0" />
<!--    <mimic joint="LFinger11" multiplier="-1" offset="0"/> -->
    <mimic joint="LHand" multiplier="-1" offset="0"/>
  </joint>

  <joint name="LThumb2" type="revolute">
    <origin xyz="0.01818 0 0" rpy="4.64506e-08 1.06465 7.88574e-08"/>
    <axis xyz="0 -1 -4.37114e-08"/>
    <parent link="LThumb1Link"/>
    <child link="LThumb2Link"/>
    <limit effort="0" lower="0" upper="1.06465082555556" velocity="0" />
<!--    <mimic joint="LFinger11" multiplier="1" offset="0"/> -->     <mimic joint="LHand" multiplier="1" offset="0"/>
  </joint>

  <joint name="LThumb3" type="revolute">
    <origin xyz="0.01818 0 0" rpy="4.64506e-08 1.06465 7.88574e-08"/>
    <axis xyz="0 -1 -4.37114e-08"/>
    <parent link="LThumb2Link"/>
    <child link="LThumb3Link"/>
    <limit effort="0" lower="0" upper="1.06465082555556" velocity="0" />
<!--    <mimic joint="LFinger11" multiplier="1" offset="0"/> -->     <mimic joint="LHand" multiplier="1" offset="0"/>
  </joint>

  <joint name="RFinger12" type="revolute">
    <origin xyz="0.01818 0 0" rpy="4.64506e-08 1.06465 7.88574e-08"/>
    <axis xyz="0 -1 -4.37114e-08"/>
    <parent link="RFinger11Link"/>
    <child link="RFinger12Link"/>
    <limit effort="0" lower="0" upper="1.06465082555556" velocity="0" />
<!--    <mimic joint="RFinger11" multiplier="1" offset="0"/> -->     <mimic joint="RHand" multiplier="1" offset="0"/>
  </joint>

  <joint name="RFinger13" type="revolute">
    <origin xyz="0.01818 0 0" rpy="4.64506e-08 1.06465 7.88574e-08"/>
    <axis xyz="0 -1 -4.37114e-08"/>
    <parent link="RFinger12Link"/>
    <child link="RFinger13Link"/>
    <limit effort="0" lower="0" upper="1.06465082555556" velocity="0" />
<!--    <mimic joint="RFinger11" multiplier="1" offset="0"/> -->     <mimic joint="RHand" multiplier="1" offset="0"/>
  </joint>

  <joint name="RFinger21" type="revolute">
    <origin xyz="0.11525 0 0.00329" rpy="4.64506e-08 1.06465 7.88574e-08"/>
    <axis xyz="0 -1 -4.37114e-08"/>
    <parent link="r_wrist"/>
    <child link="RFinger21Link"/>
    <limit effort="0" lower="0" upper="1.06465082555556" velocity="0" />
<!--    <mimic joint="RFinger11" multiplier="1" offset="0"/> -->     <mimic joint="RHand" multiplier="1" offset="0"/>
  </joint>

  <joint name="RFinger22" type="revolute">
    <origin xyz="0.01818 0 0" rpy="4.64506e-08 1.06465 7.88574e-08"/>
    <axis xyz="0 -1 -4.37114e-08"/>
    <parent link="RFinger21Link"/>
    <child link="RFinger22Link"/>
    <limit effort="0" lower="0" upper="1.06465082555556" velocity="0" />
<!--    <mimic joint="RFinger11" multiplier="1" offset="0"/> -->     <mimic joint="RHand" multiplier="1" offset="0"/>
  </joint>

  <joint name="RFinger23" type="revolute">
    <origin xyz="0.01818 0 0" rpy="4.64506e-08 1.06465 7.88574e-08"/>
    <axis xyz="0 -1 -4.37114e-08"/>
    <parent link="RFinger22Link"/>
    <child link="RFinger23Link"/>
    <limit effort="0" lower="0" upper="1.06465082555556" velocity="0" />
<!--    <mimic joint="RFinger11" multiplier="1" offset="0"/> -->     <mimic joint="RHand" multiplier="1" offset="0"/>
  </joint>

  <joint name="RFinger31" type="revolute">
    <origin xyz="0.09936 0.02478 0.00329" rpy="2.98023e-08 1.06465 0.122173"/>
    <axis xyz="0.121869 -0.992546 -4.37114e-08"/>
    <parent link="r_wrist"/>
    <child link="RFinger31Link"/>
    <limit effort="0" lower="0" upper="1.06465082555556" velocity="0" />
<!--    <mimic joint="RFinger11" multiplier="1" offset="0"/> -->     <mimic joint="RHand" multiplier="1" offset="0"/>
  </joint>

  <joint name="RFinger32" type="revolute">
    <origin xyz="0.01818 0 0" rpy="4.64506e-08 1.06465 7.88574e-08"/>
    <axis xyz="0 -1 -4.37114e-08"/>
    <parent link="RFinger31Link"/>
    <child link="RFinger32Link"/>
    <limit effort="0" lower="0" upper="1.06465082555556" velocity="0" />
<!--    <mimic joint="RFinger11" multiplier="1" offset="0"/> -->     <mimic joint="RHand" multiplier="1" offset="0"/>
  </joint>

  <joint name="RFinger33" type="revolute">
    <origin xyz="0.01818 0 0" rpy="4.64506e-08 1.06465 7.88574e-08"/>
    <axis xyz="0 -1 -4.37114e-08"/>
    <parent link="RFinger32Link"/>
    <child link="RFinger33Link"/>
    <limit effort="0" lower="0" upper="1.06465082555556" velocity="0" />
<!--    <mimic joint="RFinger11" multiplier="1" offset="0"/> -->     <mimic joint="RHand" multiplier="1" offset="0"/>
  </joint>

  <joint name="RThumb1" type="revolute">
    <origin xyz="0.07115 0.02465 -0.01233" rpy="-2.68221e-07 1.37881 2.53073"/>
    <axis xyz="0.573576 0.819152 1.05097e-07"/>
    <parent link="r_wrist"/>
    <child link="RThumb1Link"/>
    <limit effort="0" lower="-1.06465082555556" upper="0" velocity="0" />
<!--    <mimic joint="RFinger11" multiplier="-1" offset="0"/>-->
    <mimic joint="RHand" multiplier="-1" offset="0"/>
  </joint>

  <joint name="RThumb2" type="revolute">
    <origin xyz="0.01818 0 0" rpy="4.64506e-08 1.06465 7.88574e-08"/>
    <axis xyz="0 -1 -4.37114e-08"/>
    <parent link="RThumb1Link"/>
    <child link="RThumb2Link"/>
    <limit effort="0" lower="0" upper="1.06465082555556" velocity="0" />
<!--    <mimic joint="RFinger11" multiplier="1" offset="0"/> -->     <mimic joint="RHand" multiplier="1" offset="0"/>
  </joint>

  <joint name="RThumb3" type="revolute">
    <origin xyz="0.01818 0 0" rpy="4.64506e-08 1.06465 7.88574e-08"/>
    <axis xyz="0 -1 -4.37114e-08"/>
    <parent link="RThumb2Link"/>
    <child link="RThumb3Link"/>
    <limit effort="0" lower="0" upper="1.06465082555556" velocity="0" />
<!--    <mimic joint="RFinger11" multiplier="1" offset="0"/> -->     <mimic joint="RHand" multiplier="1" offset="0"/>
  </joint>

</robot>
