<?xml version="1.0" ?>
<!-- ***************************************************************** 
 ****** File automatically generated by generate_urdf.py script ****** 
 ********************************************************************* -->
<robot xmlns:xacro="http://www.ros.org/wiki/xacro">
	<joint name="LHipYaw" type="revolute">
		<parent link="body"/>
		<child link="LHipYawLink"/>
		<origin rpy="0 0 0" xyz="0 0.096 -0.20004"/>
		<axis xyz="0 0 1.0"/>
		<limit effort="9.2" lower="-0.261799" upper="0.261799" velocity="0.32"/>
	</joint>
	<link name="LHipYawLink">
		<inertial>
			<mass value="0.49477"/>
			<inertia ixx="0.00303668" ixy="0" ixz="0" iyy="0.00347998" iyz="0" izz="0.000622773"/>
			<origin rpy="0 0 0" xyz="-0.00871 -0.00022 0.06319"/>
		</inertial>
	</link>
	<joint name="LHipRoll" type="revolute">
		<parent link="LHipYawLink"/>
		<child link="LHipRollLink"/>
		<origin rpy="0 0 0" xyz="0 0 0"/>
		<axis xyz="1.0 0 0"/>
		<limit effort="46.6" lower="-0.261799" upper="0.523599" velocity="2.09"/>
	</joint>
	<link name="LHipRollLink">
		<inertial>
			<mass value="0.6607"/>
			<inertia ixx="0.00089862" ixy="0" ixz="0" iyy="0.000509559" iyz="0" izz="0.000935392"/>
			<origin rpy="0 0 0" xyz="0.00293 -0.00027 0.00011"/>
		</inertial>
	</link>
	<joint name="LHipPitch" type="revolute">
		<parent link="LHipRollLink"/>
		<child link="LHipPitchLink"/>
		<origin rpy="0 0 0" xyz="0 0 0"/>
		<axis xyz="0 1.0 0"/>
		<limit effort="46.6" lower="-1.71042" upper="0.401426" velocity="2.09"/>
	</joint>
	<link name="LHipPitchLink">
		<inertial>
			<mass value="4.33935"/>
			<inertia ixx="0.132895" ixy="0" ixz="0" iyy="0.133977" iyz="0" izz="0.0121687"/>
			<origin rpy="0 0 0" xyz="-0.00971 0.00135 -0.15083"/>
		</inertial>
		<xacro:insert_visu_LHipPitchLink/>
	</link>
	<joint name="LKneePitch" type="revolute">
		<parent link="LHipPitchLink"/>
		<child link="LKneePitchLink"/>
		<origin rpy="0 0 0" xyz="0 0 -0.32"/>
		<axis xyz="0 1.0 0"/>
		<limit effort="38.17" lower="0" upper="2.00713" velocity="6.0"/>
	</joint>
	<link name="LKneePitchLink">
		<inertial>
			<mass value="2.61063"/>
			<inertia ixx="0.054913" ixy="0" ixz="0" iyy="0.0549663" iyz="0" izz="0.00398482"/>
			<origin rpy="0 0 0" xyz="-0.00532 -0.00075 -0.12258"/>
		</inertial>
		<xacro:insert_visu_LKneePitchLink/>
	</link>
	<joint name="LAnklePitch" type="revolute">
		<parent link="LKneePitchLink"/>
		<child link="LAnklePitchLink"/>
		<origin rpy="0 0 0" xyz="0 0 -0.29"/>
		<axis xyz="0 1.0 0"/>
		<limit effort="25.76" lower="-0.523599" upper="0.785398" velocity="2.1"/>
	</joint>
	<link name="LAnklePitchLink">
		<inertial>
			<mass value="0.5008"/>
			<inertia ixx="0.000429952" ixy="0" ixz="0" iyy="0.000281451" iyz="0" izz="0.000527665"/>
			<origin rpy="0 0 0" xyz="0.00059 0.00051 0.00038"/>
		</inertial>
	</link>
	<joint name="LAnkleRoll" type="revolute">
		<parent link="LAnklePitchLink"/>
		<child link="l_ankle"/>
		<origin rpy="0 0 0" xyz="0 0 0"/>
		<axis xyz="1.0 0 0"/>
		<limit effort="25.76" lower="-0.349066" upper="0.349066" velocity="2.1"/>
	</joint>
	<link name="l_ankle">
		<inertial>
			<mass value="1.07155"/>
			<inertia ixx="0.00350696" ixy="0" ixz="0" iyy="0.0162129" iyz="0" izz="0.0147353"/>
			<origin rpy="0 0 0" xyz="0.07856 -0.00603 -0.04513"/>
		</inertial>
		<xacro:insert_visu_l_ankle/>
	</link>
	<joint name="l_sole_joint" type="fixed">
		<parent link="l_ankle"/>
		<child link="l_sole"/>
		<origin rpy="0 0 0" xyz="0 0 -0.0684"/>
	</joint>
	<link name="l_sole"/>
	<joint name="RHipYaw" type="revolute">
		<parent link="body"/>
		<child link="RHipYawLink"/>
		<origin rpy="0 0 0" xyz="0 -0.096 -0.20004"/>
		<axis xyz="0 0 1.0"/>
		<limit effort="9.2" lower="-0.261799" upper="0.261799" velocity="0.32"/>
	</joint>
	<link name="RHipYawLink">
		<inertial>
			<mass value="0.49477"/>
			<inertia ixx="0.00303668" ixy="0" ixz="0" iyy="0.00347998" iyz="0" izz="0.000622773"/>
			<origin rpy="0 0 0" xyz="-0.00871 0.00022 0.06319"/>
		</inertial>
	</link>
	<joint name="RHipRoll" type="revolute">
		<parent link="RHipYawLink"/>
		<child link="RHipRollLink"/>
		<origin rpy="0 0 0" xyz="0 0 0"/>
		<axis xyz="1.0 0 0"/>
		<limit effort="46.6" lower="-0.523599" upper="0.261799" velocity="2.09"/>
	</joint>
	<link name="RHipRollLink">
		<inertial>
			<mass value="0.6607"/>
			<inertia ixx="0.00089862" ixy="0" ixz="0" iyy="0.000509559" iyz="0" izz="0.000935392"/>
			<origin rpy="0 0 0" xyz="0.00293 0.00027 0.00011"/>
		</inertial>
	</link>
	<joint name="RHipPitch" type="revolute">
		<parent link="RHipRollLink"/>
		<child link="RHipPitchLink"/>
		<origin rpy="0 0 0" xyz="0 0 0"/>
		<axis xyz="0 1.0 0"/>
		<limit effort="46.6" lower="-1.71042" upper="0.401426" velocity="2.09"/>
	</joint>
	<link name="RHipPitchLink">
		<inertial>
			<mass value="4.33935"/>
			<inertia ixx="0.132895" ixy="0" ixz="0" iyy="0.133977" iyz="0" izz="0.0121687"/>
			<origin rpy="0 0 0" xyz="-0.00971 -0.00135 -0.15083"/>
		</inertial>
		<xacro:insert_visu_RHipPitchLink/>
	</link>
	<joint name="RKneePitch" type="revolute">
		<parent link="RHipPitchLink"/>
		<child link="RKneePitchLink"/>
		<origin rpy="0 0 0" xyz="0 0 -0.32"/>
		<axis xyz="0 1.0 0"/>
		<limit effort="38.17" lower="0" upper="2.00713" velocity="6.0"/>
	</joint>
	<link name="RKneePitchLink">
		<inertial>
			<mass value="2.61063"/>
			<inertia ixx="0.054913" ixy="0" ixz="0" iyy="0.0549663" iyz="0" izz="0.00398482"/>
			<origin rpy="0 0 0" xyz="-0.00532 0.00075 -0.12258"/>
		</inertial>
		<xacro:insert_visu_RKneePitchLink/>
	</link>
	<joint name="RAnklePitch" type="revolute">
		<parent link="RKneePitchLink"/>
		<child link="RAnklePitchLink"/>
		<origin rpy="0 0 0" xyz="0 0 -0.29"/>
		<axis xyz="0 1.0 0"/>
		<limit effort="25.76" lower="-0.523599" upper="0.785398" velocity="2.1"/>
	</joint>
	<link name="RAnklePitchLink">
		<inertial>
			<mass value="0.5008"/>
			<inertia ixx="0.000429952" ixy="0" ixz="0" iyy="0.000281451" iyz="0" izz="0.000527665"/>
			<origin rpy="0 0 0" xyz="0.00059 -0.00051 0.00038"/>
		</inertial>
	</link>
	<joint name="RAnkleRoll" type="revolute">
		<parent link="RAnklePitchLink"/>
		<child link="r_ankle"/>
		<origin rpy="0 0 0" xyz="0 0 0"/>
		<axis xyz="1.0 0 0"/>
		<limit effort="25.76" lower="-0.349066" upper="0.349066" velocity="2.1"/>
	</joint>
	<link name="r_ankle">
		<inertial>
			<mass value="1.07155"/>
			<inertia ixx="0.00350696" ixy="0" ixz="0" iyy="0.0162129" iyz="0" izz="0.0147353"/>
			<origin rpy="0 0 0" xyz="0.07856 0.00603 -0.04513"/>
		</inertial>
		<xacro:insert_visu_r_ankle/>
	</link>
	<joint name="r_sole_joint" type="fixed">
		<parent link="r_ankle"/>
		<child link="r_sole"/>
		<origin rpy="0 0 0" xyz="0 0 -0.0684"/>
	</joint>
	<link name="r_sole"/>
</robot>
