<?xml version="1.0" ?>
<!-- ***************************************************************** 
 ****** File automatically generated by generate_urdf.py script ****** 
 ********************************************************************* -->
<robot xmlns:xacro="http://www.ros.org/wiki/xacro">
	<joint name="LShoulderPitch" type="revolute">
		<parent link="torso"/>
		<child link="LShoulderPitchLink"/>
		<origin rpy="-0.158879 -0.0725189 -0.424682" xyz="0.005 0.19 0"/>
		<axis xyz="0 1.0 0"/>
		<limit effort="19.095" lower="-1.44478" upper="2.22041" velocity="2.2"/>
	</joint>
	<link name="LShoulderPitchLink">
		<inertial>
			<mass value="0.69402"/>
			<inertia ixx="0.00201004" ixy="2.37595e-06" ixz="-2.16793e-06" iyy="0.000570626" iyz="8.27832e-06" izz="0.00194068"/>
			<origin rpy="0 0 0" xyz="0.00149 -0.03299 0.00018"/>
		</inertial>
	</link>
	<joint name="LShoulderYaw" type="revolute">
		<parent link="LShoulderPitchLink"/>
		<child link="LShoulderYawLink"/>
		<origin rpy="0 0 0.430457" xyz="0 0 0"/>
		<axis xyz="0 0 1.0"/>
		<limit effort="9.031" lower="-0.430472" upper="1.14032" velocity="4.0"/>
	</joint>
	<link name="LShoulderYawLink">
		<inertial>
			<mass value="0.57151"/>
			<inertia ixx="0.000742818" ixy="-0.000617675" ixz="-7.28438e-05" iyy="0.00650202" iyz="-1.25157e-05" izz="0.00664434"/>
			<origin rpy="0 0 0" xyz="0.09367 0.01373 0.00103"/>
		</inertial>
		<xacro:insert_visu_LShoulderYawLink/>
	</link>
	<joint name="LElbowRoll" type="revolute">
		<parent link="LShoulderYawLink"/>
		<child link="LElbowRollLink"/>
		<origin rpy="0.17452 0 0" xyz="0.205 0 0"/>
		<axis xyz="1.0 0 0"/>
		<limit effort="7.404" lower="-2.0944" upper="2.0944" velocity="3.7"/>
	</joint>
	<link name="LElbowRollLink">
		<inertial>
			<mass value="0.39848"/>
			<inertia ixx="0.000179003" ixy="-2.25555e-06" ixz="1.376e-08" iyy="0.000804322" iyz="8.007e-08" izz="0.00077956"/>
			<origin rpy="0 0 0" xyz="-0.02231 -0.0024 0"/>
		</inertial>
	</link>
	<joint name="LElbowYaw" type="revolute">
		<parent link="LElbowRollLink"/>
		<child link="LElbowYawLink"/>
		<origin rpy="0 0 0" xyz="0 0 0"/>
		<axis xyz="0 0 1.0"/>
		<limit effort="6.02" lower="-1.5708" upper="0" velocity="4.0"/>
	</joint>
	<link name="LElbowYawLink">
		<inertial>
			<mass value="0.31265"/>
			<inertia ixx="0.000375096" ixy="-0.000225283" ixz="2.58073e-06" iyy="0.00209728" iyz="2.74613e-06" izz="0.00211065"/>
			<origin rpy="0 0 0" xyz="0.06738 0.01043 -0.00031"/>
		</inertial>
		<xacro:insert_visu_LElbowYawLink/>
	</link>
	<joint name="LWristRoll" type="revolute">
		<parent link="LElbowYawLink"/>
		<child link="LWristRollLink"/>
		<origin rpy="0 0 0" xyz="0.1823 0 0"/>
		<axis xyz="1.0 0 0"/>
		<limit effort="2.177" lower="-3.66519" upper="0.523599" velocity="1.1"/>
	</joint>
	<link name="LWristRollLink">
		<inertial>
			<mass value="0.17563"/>
			<inertia ixx="6.72145e-05" ixy="-6.373e-07" ixz="-1.35809e-05" iyy="0.000851196" iyz="-2.443e-08" izz="0.000840348"/>
			<origin rpy="0 0 0" xyz="-0.0593 -5e-05 -0.00069"/>
		</inertial>
		<xacro:insert_visu_LWristRollLink/>
	</link>
	<joint name="LWristYaw" type="revolute">
		<parent link="LWristRollLink"/>
		<child link="LWristYawLink"/>
		<origin rpy="0 0 0" xyz="0 0 0"/>
		<axis xyz="0 0 1.0"/>
		<limit effort="0.862" lower="-0.436332" upper="0.436332" velocity="2.26"/>
	</joint>
	<link name="LWristYawLink">
		<inertial>
			<mass value="0.07595"/>
			<inertia ixx="1.45402e-05" ixy="-4.157e-08" ixz="7.674e-08" iyy="3.91907e-05" iyz="3.08e-09" izz="3.81787e-05"/>
			<origin rpy="0 0 0" xyz="-0.00746 -0.00016 -0.00022"/>
		</inertial>
		<xacro:insert_visu_LWristYawLink/>
	</link>
	<joint name="LWristPitch" type="revolute">
		<parent link="LWristYawLink"/>
		<child link="l_wrist"/>
		<origin rpy="0 0 0" xyz="0 0 0"/>
		<axis xyz="0 1.0 0"/>
		<limit effort="0.6" lower="-0.977384" upper="0.977384" velocity="3.75"/>
	</joint>
	<link name="l_wrist">
		<inertial>
			<mass value="0.16569"/>
			<inertia ixx="0.000112529" ixy="4.72583e-05" ixz="1.70404e-05" iyy="0.00107982" iyz="-1.54761e-05" izz="0.00115367"/>
			<origin rpy="0 0 0" xyz="0.06987 -0.00381 -0.00165"/>
		</inertial>
		<xacro:insert_visu_l_wrist/>
	</link>
	<joint name="RShoulderPitch" type="revolute">
		<parent link="torso"/>
		<child link="RShoulderPitchLink"/>
		<origin rpy="0.158879 -0.0725189 0.424682" xyz="0.005 -0.19 0"/>
		<axis xyz="0 1.0 0"/>
		<limit effort="19.095" lower="-1.44478" upper="2.22041" velocity="2.2"/>
	</joint>
	<link name="RShoulderPitchLink">
		<inertial>
			<mass value="0.69402"/>
			<inertia ixx="0.00201004" ixy="-2.37595e-06" ixz="2.16793e-06" iyy="0.000570626" iyz="8.27832e-06" izz="0.00194068"/>
			<origin rpy="0 0 0" xyz="0.00149 0.03299 0.00018"/>
		</inertial>
	</link>
	<joint name="RShoulderYaw" type="revolute">
		<parent link="RShoulderPitchLink"/>
		<child link="RShoulderYawLink"/>
		<origin rpy="0 0 -0.430457" xyz="0 0 0"/>
		<axis xyz="0 0 1.0"/>
		<limit effort="9.031" lower="-1.14032" upper="0.430472" velocity="4.0"/>
	</joint>
	<link name="RShoulderYawLink">
		<inertial>
			<mass value="0.57151"/>
			<inertia ixx="0.000742356" ixy="0.000617202" ixz="5.98521e-06" iyy="0.00649989" iyz="-1.07417e-06" izz="0.000664209"/>
			<origin rpy="0 0 0" xyz="0.09367 -0.01373 0.00103"/>
		</inertial>
		<xacro:insert_visu_RShoulderYawLink/>
	</link>
	<joint name="RElbowRoll" type="revolute">
		<parent link="RShoulderYawLink"/>
		<child link="RElbowRollLink"/>
		<origin rpy="-0.17452 0 0" xyz="0.205 0 0"/>
		<axis xyz="1.0 0 0"/>
		<limit effort="7.404" lower="-2.0944" upper="2.0944" velocity="3.7"/>
	</joint>
	<link name="RElbowRollLink">
		<inertial>
			<mass value="0.39848"/>
			<inertia ixx="0.000179003" ixy="-2.25555e-06" ixz="1.376e-08" iyy="0.000804322" iyz="8.007e-08" izz="0.00077956"/>
			<origin rpy="0 0 0" xyz="-0.02231 0.0024 0"/>
		</inertial>
	</link>
	<joint name="RElbowYaw" type="revolute">
		<parent link="RElbowRollLink"/>
		<child link="RElbowYawLink"/>
		<origin rpy="0 0 0" xyz="0 0 0"/>
		<axis xyz="0 0 1.0"/>
		<limit effort="6.02" lower="0" upper="1.5708" velocity="4.0"/>
	</joint>
	<link name="RElbowYawLink">
		<inertial>
			<mass value="0.31265"/>
			<inertia ixx="0.000366728" ixy="0.000185631" ixz="-5.37905e-07" iyy="0.00211104" iyz="3.1932e-07" izz="0.000211493"/>
			<origin rpy="0 0 0" xyz="0.06738 -0.01043 -0.00031"/>
		</inertial>
		<xacro:insert_visu_RElbowYawLink/>
	</link>
	<joint name="RWristRoll" type="revolute">
		<parent link="RElbowYawLink"/>
		<child link="RWristRollLink"/>
		<origin rpy="0 0 0" xyz="0.1823 0 0"/>
		<axis xyz="1.0 0 0"/>
		<limit effort="2.177" lower="-0.523599" upper="3.66519" velocity="1.1"/>
	</joint>
	<link name="RWristRollLink">
		<inertial>
			<mass value="0.17563"/>
			<inertia ixx="6.72145e-05" ixy="-6.373e-07" ixz="-1.35809e-05" iyy="0.000851196" iyz="-2.443e-08" izz="0.000840348"/>
			<origin rpy="0 0 0" xyz="-0.0593 5e-05 -0.00069"/>
		</inertial>
		<xacro:insert_visu_RWristRollLink/>
	</link>
	<joint name="RWristYaw" type="revolute">
		<parent link="RWristRollLink"/>
		<child link="RWristYawLink"/>
		<origin rpy="0 0 0" xyz="0 0 0"/>
		<axis xyz="0 0 1.0"/>
		<limit effort="0.862" lower="-0.436332" upper="0.436332" velocity="2.26"/>
	</joint>
	<link name="RWristYawLink">
		<inertial>
			<mass value="0.07595"/>
			<inertia ixx="1.45402e-05" ixy="-4.157e-08" ixz="7.674e-08" iyy="3.91907e-05" iyz="3.08e-09" izz="3.81787e-05"/>
			<origin rpy="0 0 0" xyz="-0.00746 0.00016 -0.00022"/>
		</inertial>
		<xacro:insert_visu_RWristYawLink/>
	</link>
	<joint name="RWristPitch" type="revolute">
		<parent link="RWristYawLink"/>
		<child link="r_wrist"/>
		<origin rpy="0 0 0" xyz="0 0 0"/>
		<axis xyz="0 1.0 0"/>
		<limit effort="0.6" lower="-0.977384" upper="0.977384" velocity="3.75"/>
	</joint>
	<link name="r_wrist">
		<inertial>
			<mass value="0.16569"/>
			<inertia ixx="0.000112529" ixy="0" ixz="0" iyy="0.00107982" iyz="0" izz="0.00115367"/>
			<origin rpy="0 0 0" xyz="0.06987 0.00381 -0.00165"/>
		</inertial>
		<xacro:insert_visu_r_wrist/>
	</link>
</robot>
