<?xml version="1.0" ?>
<!--******************************************************************
 ****** File automatically generated by generate_urdf.py script ******
 *********************************************************************-->
<robot xmlns:xacro="http://www.ros.org/wiki/xacro">
	<link name="base_link"/>
	<joint name="base_link_fixedjoint" type="fixed">
		<parent link="base_link"/>
		<child link="torso"/>
		<origin rpy="0 0 0" xyz="0 0 0"/>
		<axis xyz="0 0 0"/>
	</joint>
	<link name="torso">
		<inertial>
			<mass value="5.85463"/>
			<inertia ixx="0.0587116" ixy="-3.02711e-06" ixz="0.0101426" iyy="0.0326812" iyz="-0.000132541" izz="0.0637705"/>
			<origin rpy="0 0 0" xyz="0.01512 0 0.06743"/>
		</inertial>
		<xacro:insert_visu_torso/>
	</link>
	<joint name="TrunkYaw" type="revolute">
		<parent link="torso"/>
		<child link="body"/>
		<origin rpy="0 0 0" xyz="0 0 0"/>
		<axis xyz="0 0 1.0"/>
		<limit effort="28.021" lower="-0.7575" upper="0.7575" velocity="1.5"/>
	</joint>
	<link name="body">
		<inertial>
			<mass value="5.11337"/>
			<inertia ixx="0.0564204" ixy="7.26322e-05" ixz="-0.0575115" iyy="0.0521042" iyz="-3.39086e-05" izz="0.021185"/>
			<origin rpy="0 0 0" xyz="0.02825 0 -0.16653"/>
		</inertial>
		<xacro:insert_visu_body/>
	</link>
</robot>
