<?xml version="1.0" ?>
<!--******************************************************************
 ****** File automatically generated by generate_urdf.py script ******
 *********************************************************************-->
<robot xmlns:xacro="http://www.ros.org/wiki/xacro">
	<joint name="LHipYaw_joint" type="revolute">
		<parent link="body"/>
		<child link="LHipYaw_link"/>
		<origin rpy="0 0 0" xyz="0.05 0.096 -0.3375"/>
		<axis xyz="0 0 1.0"/>
		<limit effort="25.42" lower="-0.2618" upper="0.2618" velocity="1.045"/>
	</joint>
	<link name="LHipYaw_link">
		<inertial>
			<mass value="0.51527"/>
			<inertia ixx="0.000797373" ixy="-1.0184e-06" ixz="-0.000231697" iyy="0.00131776" iyz="3.91707e-06" izz="0.000785018"/>
			<origin rpy="0 0 0" xyz="-0.00922 -0.00167 0.042"/>
		</inertial>
	</link>
	<joint name="LHipRoll_joint" type="revolute">
		<parent link="LHipYaw_link"/>
		<child link="LHip"/>
		<origin rpy="0 0 0" xyz="0 0 0"/>
		<axis xyz="1.0 0 0"/>
		<limit effort="46.6" lower="-0.2618" upper="0.5236" velocity="2.09"/>
	</joint>
	<link name="LHip">
		<inertial>
			<mass value="0.65864"/>
			<inertia ixx="0.000863659" ixy="-6.20354e-06" ixz="-1.86793e-06" iyy="0.000505068" iyz="1.24373e-06" izz="0.000938555"/>
			<origin rpy="0 0 0" xyz="0.00249 -0.00205 -0.00147"/>
		</inertial>
	</link>
	<joint name="LHipPitch_joint" type="revolute">
		<parent link="LHip"/>
		<child link="LThigh"/>
		<origin rpy="0 0 0" xyz="0 0 0"/>
		<axis xyz="0 1.0 0"/>
		<limit effort="46.6" lower="-1.6581" upper="0.4014" velocity="2.09"/>
	</joint>
	<link name="LThigh">
		<inertial>
			<mass value="4.34097"/>
			<inertia ixx="0.036002" ixy="-2.22796e-05" ixz="0.0230461" iyy="0.0364084" iyz="0.00065633" izz="0.0112971"/>
			<origin rpy="0 0 0" xyz="-0.02138 -0.00255 -0.14577"/>
		</inertial>
		<xacro:insert_visu_LThigh/>
	</link>
	<joint name="LKneePitch_joint" type="revolute">
		<parent link="LThigh"/>
		<child link="LTibia"/>
		<origin rpy="0 0 0" xyz="0 0 -0.322"/>
		<axis xyz="0 1.0 0"/>
		<limit effort="38.17" lower="-0.0218" upper="1.9722" velocity="6.0"/>
	</joint>
	<link name="LTibia">
		<inertial>
			<mass value="2.50906"/>
			<inertia ixx="0.0146626" ixy="5.06229e-08" ixz="0.00278247" iyy="0.0145661" iyz="-5.66452e-06" izz="0.00340234"/>
			<origin rpy="0 0 0" xyz="-0.00415 -0.00054 -0.11011"/>
		</inertial>
		<xacro:insert_visu_LTibia/>
	</link>
	<joint name="LAnklePitch_joint" type="revolute">
		<parent link="LTibia"/>
		<child link="LAnklePitch_link"/>
		<origin rpy="0 0 0" xyz="0 0 -0.29"/>
		<axis xyz="0 1.0 0"/>
		<limit effort="25.76" lower="-0.5149" upper="0.7505" velocity="2.1"/>
	</joint>
	<link name="LAnklePitch_link">
		<inertial>
			<mass value="0.42803"/>
			<inertia ixx="0.000338486" ixy="-1.0818e-07" ixz="9.621e-08" iyy="0.000220504" iyz="-1.13514e-06" izz="0.00039211"/>
			<origin rpy="0 0 0" xyz="0.00132 -0.00117 0.00015"/>
		</inertial>
	</link>
	<joint name="LAnkleRoll_joint" type="revolute">
		<parent link="LAnklePitch_link"/>
		<child link="l_ankle"/>
		<origin rpy="0 0 0" xyz="0 0 0"/>
		<axis xyz="1.0 0 0"/>
		<limit effort="25.76" lower="-0.3491" upper="0.3491" velocity="2.1"/>
	</joint>
	<link name="l_ankle">
		<inertial>
			<mass value="0.98379"/>
			<inertia ixx="0.000901343" ixy="-4.5809e-05" ixz="-0.000810091" iyy="0.00540559" iyz="5.65123e-05" izz="0.00543292"/>
			<origin rpy="0 0 0" xyz="0.0483878 0.00120158 -0.0367645"/>
		</inertial>
		<xacro:insert_visu_l_ankle/>
	</link>
	<joint name="LLeg_effector_fixedjoint" type="fixed">
		<parent link="l_ankle"/>
		<child link="l_sole"/>
		<origin rpy="0 0 0" xyz="0 0 -0.0651"/>
		<axis xyz="0 0 0"/>
	</joint>
	<link name="l_sole"/>
	<joint name="RHipYaw_joint" type="revolute">
		<parent link="body"/>
		<child link="RHipYaw_link"/>
		<origin rpy="0 0 0" xyz="0.05 -0.096 -0.3375"/>
		<axis xyz="0 0 1.0"/>
		<limit effort="25.42" lower="-0.2618" upper="0.2618" velocity="1.045"/>
	</joint>
	<link name="RHipYaw_link">
		<inertial>
			<mass value="0.51527"/>
			<inertia ixx="0.000797373" ixy="-1.6886e-05" ixz="-0.000231697" iyy="0.00131776" iyz="7.61991e-05" izz="0.000785018"/>
			<origin rpy="0 0 0" xyz="-0.00922 0.00167 0.042"/>
		</inertial>
	</link>
	<joint name="RHipRoll_joint" type="revolute">
		<parent link="RHipYaw_link"/>
		<child link="RHip"/>
		<origin rpy="0 0 0" xyz="0 0 0"/>
		<axis xyz="1.0 0 0"/>
		<limit effort="46.6" lower="-0.5236" upper="0.2618" velocity="2.09"/>
	</joint>
	<link name="RHip">
		<inertial>
			<mass value="0.65864"/>
			<inertia ixx="0.000863659" ixy="5.20518e-07" ixz="-1.86793e-06" iyy="0.000505068" iyz="-2.72589e-06" izz="0.000938555"/>
			<origin rpy="0 0 0" xyz="0.00249 0.00205 -0.00147"/>
		</inertial>
	</link>
	<joint name="RHipPitch_joint" type="revolute">
		<parent link="RHip"/>
		<child link="RThigh"/>
		<origin rpy="0 0 0" xyz="0 0 0"/>
		<axis xyz="0 1.0 0"/>
		<limit effort="46.6" lower="-1.6581" upper="0.4014" velocity="2.09"/>
	</joint>
	<link name="RThigh">
		<inertial>
			<mass value="4.34097"/>
			<inertia ixx="0.036002" ixy="-0.00049561" ixz="0.0230461" iyy="0.0364084" iyz="-0.00257086" izz="0.0112971"/>
			<origin rpy="0 0 0" xyz="-0.02138 0.00255 -0.14577"/>
		</inertial>
		<xacro:insert_visu_RThigh/>
	</link>
	<joint name="RKneePitch_joint" type="revolute">
		<parent link="RThigh"/>
		<child link="RTibia"/>
		<origin rpy="0 0 0" xyz="0 0 -0.322"/>
		<axis xyz="0 1.0 0"/>
		<limit effort="38.17" lower="-0.0218" upper="1.9722" velocity="6.0"/>
	</joint>
	<link name="RTibia">
		<inertial>
			<mass value="2.50906"/>
			<inertia ixx="0.0146626" ixy="-1.1195e-05" ixz="0.00278247" iyy="0.0145661" iyz="-0.000304039" izz="0.00340234"/>
			<origin rpy="0 0 0" xyz="-0.00415 0.00054 -0.11011"/>
		</inertial>
		<xacro:insert_visu_RTibia/>
	</link>
	<joint name="RAnklePitch_joint" type="revolute">
		<parent link="RTibia"/>
		<child link="RAnklePitch_link"/>
		<origin rpy="0 0 0" xyz="0 0 -0.29"/>
		<axis xyz="0 1.0 0"/>
		<limit effort="25.76" lower="-0.5149" upper="0.7505" velocity="2.1"/>
	</joint>
	<link name="RAnklePitch_link">
		<inertial>
			<mass value="0.42803"/>
			<inertia ixx="0.000338486" ixy="1.21392e-06" ixz="9.621e-08" iyy="0.000220504" iyz="-9.84901e-07" izz="0.00039211"/>
			<origin rpy="0 0 0" xyz="0.00132 0.00117 0.00015"/>
		</inertial>
	</link>
	<joint name="RAnkleRoll_joint" type="revolute">
		<parent link="RAnklePitch_link"/>
		<child link="r_ankle"/>
		<origin rpy="0 0 0" xyz="0 0 0"/>
		<axis xyz="1.0 0 0"/>
		<limit effort="25.76" lower="-0.3491" upper="0.3491" velocity="2.1"/>
	</joint>
	<link name="r_ankle">
		<inertial>
			<mass value="0.98379"/>
			<inertia ixx="0.000901343" ixy="-0.000160208" ixz="-0.000810091" iyy="0.00540559" iyz="0.000143431" izz="0.00543292"/>
			<origin rpy="0 0 0" xyz="0.0483878 -0.00120158 -0.0367645"/>
		</inertial>
		<xacro:insert_visu_r_ankle/>
	</link>
	<joint name="RLeg_effector_fixedjoint" type="fixed">
		<parent link="r_ankle"/>
		<child link="r_sole"/>
		<origin rpy="0 0 0" xyz="0 0 -0.0651"/>
		<axis xyz="0 0 0"/>
	</joint>
	<link name="r_sole"/>
</robot>
