<?xml version="1.0" ?>
<!--******************************************************************
 ****** File automatically generated by generate_urdf.py script ******
 *********************************************************************-->
<robot xmlns:xacro="http://www.ros.org/wiki/xacro">
	<joint name="NeckYaw" type="revolute">
		<parent link="torso"/>
		<child link="NeckYaw_link"/>
		<origin rpy="0 -2.98023e-08 0" xyz="0.0548 0 0.1675"/>
		<axis xyz="0.173651 0 0.984807"/>
		<limit effort="3.662" lower="-2.0595" upper="2.0595" velocity="4.0"/>
	</joint>
	<link name="NeckYaw_link">
		<inertial>
			<mass value="0.32745"/>
			<inertia ixx="0.000242012" ixy="-2.69441e-07" ixz="-1.29328e-05" iyy="0.000225485" iyz="-6.99834e-07" izz="7.29248e-05"/>
			<origin rpy="0 0 0" xyz="-0.00635646 0 -0.030002"/>
		</inertial>
	</link>
	<joint name="NeckPitch" type="revolute">
		<parent link="NeckYaw_link"/>
		<child link="NeckPitch_link"/>
		<origin rpy="0 -2.98023e-08 0" xyz="0 0 0"/>
		<axis xyz="0 1.0 0"/>
		<limit effort="2.978" lower="-0.3142" upper="0.6632" velocity="2.2"/>
	</joint>
	<link name="NeckPitch_link">
		<inertial>
			<mass value="0.29923"/>
			<inertia ixx="0.000412832" ixy="-1.67846e-06" ixz="0.000111721" iyy="0.000383921" iyz="5.04259e-05" izz="0.000264006"/>
			<origin rpy="0 0 0" xyz="0.00372 0 0.04811"/>
		</inertial>
		<xacro:insert_visu_NeckPitch_link/>
	</link>
	<joint name="HeadPitch" type="revolute">
		<parent link="NeckPitch_link"/>
		<child link="HeadPitch_link"/>
		<origin rpy="0 0 0" xyz="0 0 0.0951"/>
		<axis xyz="0 1.0 0"/>
		<limit effort="2.57" lower="-0.2571" upper="0.2971" velocity="1.9"/>
	</joint>
	<link name="HeadPitch_link">
		<inertial>
			<mass value="0.13728"/>
			<inertia ixx="2.23022e-05" ixy="1.3103e-07" ixz="-1.31933e-05" iyy="6.44652e-05" iyz="-4.26e-09" izz="5.78637e-05"/>
			<origin rpy="0 0 0" xyz="0.0014 0 -0.00462"/>
		</inertial>
	</link>
	<joint name="HeadRoll" type="revolute">
		<parent link="HeadPitch_link"/>
		<child link="HeadRoll_link"/>
		<origin rpy="0 0 0" xyz="0 0 0"/>
		<axis xyz="1.0 0 0"/>
		<limit effort="0.9" lower="-0.4887" upper="0.4887" velocity="1.5"/>
	</joint>
	<link name="HeadRoll_link">
		<inertial>
			<mass value="1.79432"/>
			<inertia ixx="0.00808695" ixy="-3.36239e-05" ixz="0.00239535" iyy="0.00960886" iyz="0.000260292" izz="0.00796332"/>
			<origin rpy="0 0 0" xyz="0.01263 0 0.07498"/>
		</inertial>
		<xacro:insert_visu_HeadRoll_link/>
	</link>
	<joint name="gaze_joint" type="fixed">
		<parent link="HeadRoll_link"/>
		<child link="gaze"/>
		<origin rpy="0 0 0" xyz="0.10247 0 0.05425"/>
	</joint>
	<link name="gaze"/>
</robot>
