<?xml version="1.0" ?>
<!--******************************************************************
 ****** File automatically generated by generate_urdf.py script ******
 *********************************************************************-->
<robot xmlns:xacro="http://www.ros.org/wiki/xacro">
	<joint name="LShoulderPitch_joint" type="revolute">
		<parent link="torso"/>
		<child link="LShoulder"/>
		<origin rpy="1.49012e-08 7.45058e-09 0" xyz="0.049862 0.19 0.073851"/>
		<axis xyz="0.417025 0.895055 -0.15801"/>
		<limit effort="19.095" lower="-1.3491" upper="2.2462" velocity="2.2"/>
	</joint>
	<link name="LShoulder">
		<inertial>
			<mass value="0.43527"/>
			<inertia ixx="0.000268738" ixy="-7.98278e-05" ixz="8.02495e-06" iyy="0.000151197" iyz="1.72313e-05" izz="0.000290161"/>
			<origin rpy="0 0 0" xyz="-0.0112798 -0.0260712 0.00468882"/>
		</inertial>
	</link>
	<joint name="LShoulderYaw_joint" type="revolute">
		<parent link="LShoulder"/>
		<child link="LShoulderYaw_link"/>
		<origin rpy="2.98023e-08 1.11759e-08 -5.58793e-08" xyz="0 0 0"/>
		<axis xyz="0.0401398 0.155542 0.987013"/>
		<limit effort="9.031" lower="-0.5768" upper="0.9242" velocity="4.0"/>
	</joint>
	<link name="LShoulderYaw_link">
		<inertial>
			<mass value="0.69262"/>
			<inertia ixx="0.000953111" ixy="0.000479248" ixz="0.000898232" iyy="0.00250956" iyz="-1.65544e-05" izz="0.00233103"/>
			<origin rpy="0 0 0" xyz="0.0965281 0.00465308 0.00168775"/>
		</inertial>
		<xacro:insert_visu_LShoulderYaw_link/>
	</link>
	<joint name="LElbowRoll_joint" type="revolute">
		<parent link="LShoulderYaw_link"/>
		<child link="LForeArm"/>
		<origin rpy="-2.56114e-09 0 -9.31322e-09" xyz="0.210824 7.40511e-09 -0.008631"/>
		<axis xyz="0.998889 0.0139984 0.044995"/>
		<limit effort="7.404" lower="-2.2148" upper="1.9042" velocity="3.7"/>
	</joint>
	<link name="LForeArm">
		<inertial>
			<mass value="0.48271"/>
			<inertia ixx="0.000166894" ixy="9.68978e-06" ixz="-1.49781e-05" iyy="0.000408141" iyz="1.2555e-06" izz="0.00036684"/>
			<origin rpy="0 0 0" xyz="-0.0348859 -0.0011589 -0.00148134"/>
		</inertial>
	</link>
	<joint name="LElbowYaw_joint" type="revolute">
		<parent link="LForeArm"/>
		<child link="LElbow"/>
		<origin rpy="-1.49504e-08 -1.86264e-08 2.12577e-09" xyz="0 0 0"/>
		<axis xyz="-0.0449994 0 0.998987"/>
		<limit effort="6.02" lower="-1.5228" upper="0.0044" velocity="4.0"/>
	</joint>
	<link name="LElbow">
		<inertial>
			<mass value="0.36997"/>
			<inertia ixx="0.000404839" ixy="0.000470943" ixz="2.57237e-05" iyy="0.00102723" iyz="2.9528e-05" izz="0.000987329"/>
			<origin rpy="0 0 0" xyz="0.068523 0.0097 0.00458766"/>
		</inertial>
		<xacro:insert_visu_LElbow/>
	</link>
	<joint name="LWristRoll_joint" type="revolute">
		<parent link="LElbow"/>
		<child link="LWristRoll_link"/>
		<origin rpy="0 -7.45058e-09 0" xyz="0.190404 0 0.008631"/>
		<axis xyz="0.998987 0 0.0449994"/>
		<limit effort="2.177" lower="-3.6303" upper="0.4887" velocity="1.1"/>
	</joint>
	<link name="LWristRoll_link">
		<inertial>
			<mass value="0.17551"/>
			<inertia ixx="8.1046e-05" ixy="-1.46219e-06" ixz="-3.67139e-05" iyy="0.000308979" iyz="-8.92509e-08" izz="0.000294305"/>
			<origin rpy="0 0 0" xyz="-0.0592449 6e-05 -0.00144745"/>
		</inertial>
		<xacro:insert_visu_LWristRoll_link/>
	</link>
	<joint name="LWristYaw_joint" type="revolute">
		<parent link="LWristRoll_link"/>
		<child link="LWristYaw_link"/>
		<origin rpy="0 0 0" xyz="0 0 0"/>
		<axis xyz="-0.0449994 0 0.998987"/>
		<limit effort="0.862" lower="-0.4014" upper="0.4014" velocity="2.26"/>
	</joint>
	<link name="LWristYaw_link">
		<inertial>
			<mass value="0.061"/>
			<inertia ixx="1.25161e-05" ixy="-4.16668e-08" ixz="-7.01768e-07" iyy="2.83374e-05" iyz="1.56375e-08" izz="2.79694e-05"/>
			<origin rpy="0 0 0" xyz="-0.00657144 0.00017 -0.000115829"/>
		</inertial>
		<xacro:insert_visu_LWristYaw_link/>
	</link>
	<joint name="LWristPitch_joint" type="revolute">
		<parent link="LWristYaw_link"/>
		<child link="l_wrist"/>
		<origin rpy="0 0 0" xyz="0 0 0"/>
		<axis xyz="0 1.0 0"/>
		<limit effort="0.6" lower="-0.988" upper="0.8969" velocity="3.75"/>
	</joint>
	<link name="l_wrist">
		<inertial>
			<mass value="0.35549"/>
			<inertia ixx="0.000325271" ixy="-0.000324985" ixz="1.52493e-05" iyy="0.000666741" iyz="6.27901e-05" izz="0.000820118"/>
			<origin rpy="0 0 0" xyz="0.07358 -0.00628 -0.00098"/>
		</inertial>
		<xacro:insert_visu_l_wrist/>
	</link>
	<joint name="LHand_actuator" type="revolute">
		<parent link="l_wrist"/>
		<child link="l_gripper"/>
		<origin rpy="1.5708 0.0450146 -3.14159" xyz="-0.0579412 -0.0159 -0.00260997"/>
		<axis xyz="1.0 0 0"/>
		<limit effort="0.649997" lower="0" upper="1.0" velocity="59.8925"/>
	</joint>
	<link name="l_gripper"/>
	<joint name="RShoulderPitch_joint" type="revolute">
		<parent link="torso"/>
		<child link="RShoulder"/>
		<origin rpy="-1.49012e-08 7.45058e-09 0" xyz="0.049862 -0.19 0.073851"/>
		<axis xyz="-0.417025 0.895055 0.15801"/>
		<limit effort="19.095" lower="-1.4554" upper="2.1399" velocity="2.2"/>
	</joint>
	<link name="RShoulder">
		<inertial>
			<mass value="0.43527"/>
			<inertia ixx="0.000264235" ixy="8.24341e-05" ixz="1.55448e-05" iyy="0.000160752" iyz="-3.06968e-05" izz="0.000285109"/>
			<origin rpy="0 0 0" xyz="-0.0112798 0.0260712 0.00468882"/>
		</inertial>
	</link>
	<joint name="RShoulderYaw_joint" type="revolute">
		<parent link="RShoulder"/>
		<child link="RShoulderYaw_link"/>
		<origin rpy="-2.98023e-08 1.49012e-08 -6.42613e-08" xyz="0 0 0"/>
		<axis xyz="0.0401398 -0.155542 0.987014"/>
		<limit effort="9.031" lower="-1.0985" upper="0.4025" velocity="4.0"/>
	</joint>
	<link name="RShoulderYaw_link">
		<inertial>
			<mass value="0.69262"/>
			<inertia ixx="0.000955527" ixy="-0.000291705" ixz="0.000927729" iyy="0.00250758" iyz="1.49948e-05" izz="0.00233059"/>
			<origin rpy="0 0 0" xyz="0.0965281 -0.00465308 0.00168775"/>
		</inertial>
		<xacro:insert_visu_RShoulderYaw_link/>
	</link>
	<joint name="RElbowRoll_joint" type="revolute">
		<parent link="RShoulderYaw_link"/>
		<child link="RForeArm"/>
		<origin rpy="6.69388e-09 7.45058e-09 -7.91624e-08" xyz="0.210824 -1.48548e-08 -0.008631"/>
		<axis xyz="0.998889 -0.0139984 0.044995"/>
		<limit effort="7.404" lower="-1.9047" upper="2.2143" velocity="3.7"/>
	</joint>
	<link name="RForeArm">
		<inertial>
			<mass value="0.48271"/>
			<inertia ixx="0.000166993" ixy="-6.12728e-06" ixz="-1.49476e-05" iyy="0.000408038" iyz="7.67117e-07" izz="0.000366843"/>
			<origin rpy="0 0 0" xyz="-0.0348859 0.0011589 -0.00148134"/>
		</inertial>
	</link>
	<joint name="RElbowYaw_joint" type="revolute">
		<parent link="RForeArm"/>
		<child link="RElbow"/>
		<origin rpy="1.49504e-08 -1.86264e-08 -2.12577e-09" xyz="0 0 0"/>
		<axis xyz="-0.0449994 0 0.998987"/>
		<limit effort="6.02" lower="-0.0047" upper="1.5225" velocity="4.0"/>
	</joint>
	<link name="RElbow">
		<inertial>
			<mass value="0.36997"/>
			<inertia ixx="0.000404839" ixy="-2.08748e-05" ixz="2.57237e-05" iyy="0.00102723" iyz="-3.39957e-06" izz="0.000987329"/>
			<origin rpy="0 0 0" xyz="0.068523 -0.0097 0.00458766"/>
		</inertial>
		<xacro:insert_visu_RElbow/>
	</link>
	<joint name="RWristRoll_joint" type="revolute">
		<parent link="RElbow"/>
		<child link="RWristRoll_link"/>
		<origin rpy="0 -7.45058e-09 0" xyz="0.190404 0 0.008631"/>
		<axis xyz="0.998987 0 0.0449994"/>
		<limit effort="2.177" lower="-0.4887" upper="3.6303" velocity="1.1"/>
	</joint>
	<link name="RWristRoll_link">
		<inertial>
			<mass value="0.17551"/>
			<inertia ixx="8.1046e-05" ixy="-2.14425e-07" ixz="-3.67139e-05" iyy="0.000308979" iyz="-5.87658e-08" izz="0.000294305"/>
			<origin rpy="0 0 0" xyz="-0.0592449 -6e-05 -0.00144745"/>
		</inertial>
		<xacro:insert_visu_RWristRoll_link/>
	</link>
	<joint name="RWristYaw_joint" type="revolute">
		<parent link="RWristRoll_link"/>
		<child link="RWristYaw_link"/>
		<origin rpy="0 0 0" xyz="0 0 0"/>
		<axis xyz="-0.0449994 0 0.998987"/>
		<limit effort="0.862" lower="-0.4014" upper="0.4014" velocity="2.26"/>
	</joint>
	<link name="RWristYaw_link">
		<inertial>
			<mass value="0.061"/>
			<inertia ixx="1.25161e-05" ixy="9.4625e-08" ixz="-7.01768e-07" iyy="2.83374e-05" iyz="1.80397e-08" izz="2.79694e-05"/>
			<origin rpy="0 0 0" xyz="-0.00657144 -0.00017 -0.000115829"/>
		</inertial>
		<xacro:insert_visu_RWristYaw_link/>
	</link>
	<joint name="RWristPitch_joint" type="revolute">
		<parent link="RWristYaw_link"/>
		<child link="r_wrist"/>
		<origin rpy="0 0 0" xyz="0 0 0"/>
		<axis xyz="0 1.0 0"/>
		<limit effort="0.6" lower="-0.9868" upper="0.8981" velocity="3.75"/>
	</joint>
	<link name="r_wrist">
		<inertial>
			<mass value="0.35549"/>
			<inertia ixx="0.000325271" ixy="3.54589e-06" ixz="1.52493e-05" iyy="0.000666741" iyz="5.84145e-05" izz="0.000820118"/>
			<origin rpy="0 0 0" xyz="0.07358 0.00628 -0.00098"/>
		</inertial>
		<xacro:insert_visu_r_wrist/>
	</link>
	<joint name="RHand_actuator" type="revolute">
		<parent link="r_wrist"/>
		<child link="r_gripper"/>
		<origin rpy="1.5708 0.0450146 -3.14159" xyz="-0.0579412 -0.0159 -0.00260997"/>
		<axis xyz="1.0 0 0"/>
		<limit effort="0.649997" lower="0" upper="1.0" velocity="59.8925"/>
	</joint>
	<link name="r_gripper"/>
</robot>
