<?xml version="1.0" ?>
<!--******************************************************************
 ****** File automatically generated by generate_urdf.py script ******
 *********************************************************************-->
<robot name="romeoH37" xmlns:xacro="http://www.ros.org/wiki/xacro">
	<link name="RFinger13_link">
		<xacro:insert_visu_RFinger13_link/>
	</link>
	<joint name="RFinger13_joint" type="continuous">
		<parent link="RFinger12_link"/>
		<child link="RFinger13_link"/>
		<origin rpy="0 0 0" xyz="0 0.0230916 -5.90086e-06"/>
		<axis xyz="0 0 1.0"/>
		<mimic joint="RHand_actuator" multiplier="0.988205" offset="0"/>
	</joint>
	<link name="RFinger12_link">
		<xacro:insert_visu_RFinger12_link/>
	</link>
	<joint name="RFinger12_joint" type="continuous">
		<parent link="RFinger11_link"/>
		<child link="RFinger12_link"/>
		<origin rpy="0 0 0" xyz="0 0.0230929 4.02331e-06"/>
		<axis xyz="0 0 1.0"/>
		<mimic joint="RHand_actuator" multiplier="0.988205" offset="0"/>
	</joint>
	<link name="LFinger33_link">
		<xacro:insert_visu_LFinger33_link/>
	</link>
	<joint name="LFinger33_joint" type="continuous">
		<parent link="LFinger32_link"/>
		<child link="LFinger33_link"/>
		<origin rpy="0 0 0" xyz="0 0.0230916 -5.91576e-06"/>
		<axis xyz="0 0 1.0"/>
		<mimic joint="LHand_actuator" multiplier="0.988205" offset="0"/>
	</joint>
	<link name="RFinger31_link">
		<xacro:insert_visu_RFinger31_link/>
	</link>
	<joint name="RFinger31_joint" type="continuous">
		<parent link="r_wrist"/>
		<child link="RFinger31_link"/>
		<origin rpy="1.69304 1.5708 3.14159" xyz="0.11215 -0.03024 0.00999"/>
		<axis xyz="0 0 1.0"/>
		<mimic joint="RHand_actuator" multiplier="0.988205" offset="0"/>
	</joint>
	<link name="RFinger32_link">
		<xacro:insert_visu_RFinger32_link/>
	</link>
	<joint name="RFinger32_joint" type="continuous">
		<parent link="RFinger31_link"/>
		<child link="RFinger32_link"/>
		<origin rpy="0 0 0" xyz="0 -0.0230929 -4.02331e-06"/>
		<axis xyz="0 0 1.0"/>
		<mimic joint="RHand_actuator" multiplier="0.988205" offset="0"/>
	</joint>
	<link name="LFinger21_link">
		<xacro:insert_visu_LFinger21_link/>
	</link>
	<joint name="LFinger21_joint" type="continuous">
		<parent link="l_wrist"/>
		<child link="LFinger21_link"/>
		<origin rpy="1.5708 1.5708 3.14159" xyz="0.12934 0 0.01499"/>
		<axis xyz="0 0 1.0"/>
		<mimic joint="LHand_actuator" multiplier="0.988205" offset="0"/>
	</joint>
	<link name="LFinger13_link">
		<xacro:insert_visu_LFinger13_link/>
	</link>
	<joint name="LFinger13_joint" type="continuous">
		<parent link="LFinger12_link"/>
		<child link="LFinger13_link"/>
		<origin rpy="0 0 0" xyz="0 -0.0230916 5.90086e-06"/>
		<axis xyz="0 0 1.0"/>
		<mimic joint="LHand_actuator" multiplier="0.988205" offset="0"/>
	</joint>
	<link name="LFinger32_link">
		<xacro:insert_visu_LFinger32_link/>
	</link>
	<joint name="LFinger32_joint" type="continuous">
		<parent link="LFinger31_link"/>
		<child link="LFinger32_link"/>
		<origin rpy="0 0 0" xyz="0 0.0230928 4.02331e-06"/>
		<axis xyz="0 0 1.0"/>
		<mimic joint="LHand_actuator" multiplier="0.988205" offset="0"/>
	</joint>
	<link name="LFinger11_link">
		<xacro:insert_visu_LFinger11_link/>
	</link>
	<joint name="LFinger11_joint" type="continuous">
		<parent link="l_wrist"/>
		<child link="LFinger11_link"/>
		<origin rpy="1.69304 1.5708 3.14159" xyz="0.12385 -0.03024 0.00999"/>
		<axis xyz="0 0 1.0"/>
		<mimic joint="LHand_actuator" multiplier="0.988205" offset="0"/>
	</joint>
	<link name="RFinger22_link">
		<xacro:insert_visu_RFinger22_link/>
	</link>
	<joint name="RFinger22_joint" type="continuous">
		<parent link="RFinger21_link"/>
		<child link="RFinger22_link"/>
		<origin rpy="0 0 0" xyz="0 0.02309 0"/>
		<axis xyz="0 0 1.0"/>
		<mimic joint="RHand_actuator" multiplier="0.988205" offset="0"/>
	</joint>
	<link name="LFinger22_link">
		<xacro:insert_visu_LFinger22_link/>
	</link>
	<joint name="LFinger22_joint" type="continuous">
		<parent link="LFinger21_link"/>
		<child link="LFinger22_link"/>
		<origin rpy="0 0 0" xyz="0 -0.02309 0"/>
		<axis xyz="0 0 1.0"/>
		<mimic joint="LHand_actuator" multiplier="0.988205" offset="0"/>
	</joint>
	<link name="RFinger21_link">
		<xacro:insert_visu_RFinger21_link/>
	</link>
	<joint name="RFinger21_joint" type="continuous">
		<parent link="r_wrist"/>
		<child link="RFinger21_link"/>
		<origin rpy="1.5708 -1.5708 -3.14159" xyz="0.12934 0 0.01499"/>
		<axis xyz="0 0 1.0"/>
		<mimic joint="RHand_actuator" multiplier="0.988205" offset="0"/>
	</joint>
	<link name="LFinger12_link">
		<xacro:insert_visu_LFinger12_link/>
	</link>
	<joint name="LFinger12_joint" type="continuous">
		<parent link="LFinger11_link"/>
		<child link="LFinger12_link"/>
		<origin rpy="0 0 0" xyz="0 -0.0230929 -4.02331e-06"/>
		<axis xyz="0 0 1.0"/>
		<mimic joint="LHand_actuator" multiplier="0.988205" offset="0"/>
	</joint>
	<link name="RFinger23_link">
		<xacro:insert_visu_RFinger23_link/>
	</link>
	<joint name="RFinger23_joint" type="continuous">
		<parent link="RFinger22_link"/>
		<child link="RFinger23_link"/>
		<origin rpy="0 0 0" xyz="0 0.02309 0"/>
		<axis xyz="0 0 1.0"/>
		<mimic joint="RHand_actuator" multiplier="0.988205" offset="0"/>
	</joint>
	<link name="RFinger11_link">
		<xacro:insert_visu_RFinger11_link/>
	</link>
	<joint name="RFinger11_joint" type="continuous">
		<parent link="r_wrist"/>
		<child link="RFinger11_link"/>
		<origin rpy="1.69304 -1.5708 3.14159" xyz="0.12385 0.03024 0.00999"/>
		<axis xyz="0 0 1.0"/>
		<mimic joint="RHand_actuator" multiplier="0.988205" offset="0"/>
	</joint>
	<link name="LFinger23_link">
		<xacro:insert_visu_LFinger23_link/>
	</link>
	<joint name="LFinger23_joint" type="continuous">
		<parent link="LFinger22_link"/>
		<child link="LFinger23_link"/>
		<origin rpy="0 0 0" xyz="0 -0.02309 0"/>
		<axis xyz="0 0 1.0"/>
		<mimic joint="LHand_actuator" multiplier="0.988205" offset="0"/>
	</joint>
	<link name="LFinger31_link">
		<xacro:insert_visu_LFinger31_link/>
	</link>
	<joint name="LFinger31_joint" type="continuous">
		<parent link="l_wrist"/>
		<child link="LFinger31_link"/>
		<origin rpy="1.69304 -1.5708 3.14159" xyz="0.11215 0.03024 0.00999"/>
		<axis xyz="0 0 1.0"/>
		<mimic joint="LHand_actuator" multiplier="0.988205" offset="0"/>
	</joint>
	<link name="RFinger33_link">
		<xacro:insert_visu_RFinger33_link/>
	</link>
	<joint name="RFinger33_joint" type="continuous">
		<parent link="RFinger32_link"/>
		<child link="RFinger33_link"/>
		<origin rpy="0 0 0" xyz="0 -0.0230916 5.90086e-06"/>
		<axis xyz="0 0 1.0"/>
		<mimic joint="RHand_actuator" multiplier="0.988205" offset="0"/>
	</joint>
	<link name="LThumb3_link">
		<xacro:insert_visu_LThumb3_link/>
	</link>
	<joint name="LThumb3_joint" type="continuous">
		<parent link="LThumb2_link"/>
		<child link="LThumb3_link"/>
		<origin rpy="-5.96047e-08 0 1.49012e-08" xyz="0.0187362 0.0135152 5.21541e-06"/>
		<axis xyz="0 0 1.0"/>
		<mimic joint="LHand_actuator" multiplier="0.988205" offset="0"/>
	</joint>
	<link name="LThumb1_link">
		<xacro:insert_visu_LThumb1_link/>
	</link>
	<joint name="LThumb1_joint" type="continuous">
		<parent link="l_wrist"/>
		<child link="LThumb1_link"/>
		<origin rpy="-2.97779 1.21665 -3.14159" xyz="0.0624 -0.03131 -0.00574"/>
		<axis xyz="0 0 1.0"/>
		<mimic joint="LHand_actuator" multiplier="1.74533" offset="0"/>
	</joint>
	<link name="RThumb1_link">
		<xacro:insert_visu_RThumb1_link/>
	</link>
	<joint name="RThumb1_joint" type="continuous">
		<parent link="r_wrist"/>
		<child link="RThumb1_link"/>
		<origin rpy="0.1638 -1.21665 0" xyz="0.0624 0.03131 -0.00574"/>
		<axis xyz="0 0 1.0"/>
		<mimic joint="RHand_actuator" multiplier="1.74533" offset="0"/>
	</joint>
	<link name="RThumb2_link">
		<xacro:insert_visu_RThumb2_link/>
	</link>
	<joint name="RThumb2_joint" type="continuous">
		<parent link="RThumb1_link"/>
		<child link="RThumb2_link"/>
		<origin rpy="1.13316 0 -1.80698" xyz="-0.000329241 0.0388865 -0.017011"/>
		<axis xyz="0 0 1.0"/>
		<mimic joint="RHand_actuator" multiplier="0.988205" offset="0"/>
	</joint>
	<link name="LThumb2_link">
		<xacro:insert_visu_LThumb2_link/>
	</link>
	<joint name="LThumb2_joint" type="continuous">
		<parent link="LThumb1_link"/>
		<child link="LThumb2_link"/>
		<origin rpy="1.13316 7.45058e-09 -1.80698" xyz="0.000329241 -0.0388865 0.017011"/>
		<axis xyz="0 0 1.0"/>
		<mimic joint="LHand_actuator" multiplier="0.988205" offset="0"/>
	</joint>
	<link name="RThumb3_link">
		<xacro:insert_visu_RThumb3_link/>
	</link>
	<joint name="RThumb3_joint" type="continuous">
		<parent link="RThumb2_link"/>
		<child link="RThumb3_link"/>
		<origin rpy="-5.96047e-08 -1.49012e-08 1.49012e-08" xyz="-0.0187362 -0.0135152 -5.21541e-06"/>
		<axis xyz="0 0 1.0"/>
		<mimic joint="RHand_actuator" multiplier="0.988205" offset="0"/>
	</joint>
</robot>
